[2022-03-13 10:26:37,497] {taskinstance.py:1037} INFO - Dependencies all met for <TaskInstance: 1_init_once_seed_data.load_seed_data_once scheduled__2020-08-01T00:00:00+00:00 [queued]>
[2022-03-13 10:26:37,511] {taskinstance.py:1037} INFO - Dependencies all met for <TaskInstance: 1_init_once_seed_data.load_seed_data_once scheduled__2020-08-01T00:00:00+00:00 [queued]>
[2022-03-13 10:26:37,512] {taskinstance.py:1243} INFO - 
--------------------------------------------------------------------------------
[2022-03-13 10:26:37,512] {taskinstance.py:1244} INFO - Starting attempt 1 of 1
[2022-03-13 10:26:37,512] {taskinstance.py:1245} INFO - 
--------------------------------------------------------------------------------
[2022-03-13 10:26:37,528] {taskinstance.py:1264} INFO - Executing <Task(BashOperator): load_seed_data_once> on 2020-08-01 00:00:00+00:00
[2022-03-13 10:26:37,533] {standard_task_runner.py:52} INFO - Started process 334 to run task
[2022-03-13 10:26:37,536] {standard_task_runner.py:76} INFO - Running: ['***', 'tasks', 'run', '1_init_once_seed_data', 'load_seed_data_once', 'scheduled__2020-08-01T00:00:00+00:00', '--job-id', '4', '--raw', '--subdir', 'DAGS_FOLDER/init.py', '--cfg-path', '/tmp/tmpnhrm3hm3', '--error-file', '/tmp/tmpths2i44z']
[2022-03-13 10:26:37,537] {standard_task_runner.py:77} INFO - Job 4: Subtask load_seed_data_once
[2022-03-13 10:26:37,604] {logging_mixin.py:109} INFO - Running <TaskInstance: 1_init_once_seed_data.load_seed_data_once scheduled__2020-08-01T00:00:00+00:00 [running]> on host fec3c11ce99f
[2022-03-13 10:26:37,735] {taskinstance.py:1431} INFO - Exporting the following env vars:
AIRFLOW_CTX_DAG_OWNER=***
AIRFLOW_CTX_DAG_ID=1_init_once_seed_data
AIRFLOW_CTX_TASK_ID=load_seed_data_once
AIRFLOW_CTX_EXECUTION_DATE=2020-08-01T00:00:00+00:00
AIRFLOW_CTX_DAG_RUN_ID=scheduled__2020-08-01T00:00:00+00:00
[2022-03-13 10:26:37,735] {subprocess.py:62} INFO - Tmp dir root location: 
 /tmp
[2022-03-13 10:26:37,736] {subprocess.py:74} INFO - Running command: ['bash', '-c', 'cd /dbt && dbt seed --profiles-dir .']
[2022-03-13 10:26:37,746] {subprocess.py:85} INFO - Output:
[2022-03-13 10:26:37,748] {subprocess.py:89} INFO - bash: line 0: cd: /dbt: No such file or directory
[2022-03-13 10:26:37,748] {subprocess.py:93} INFO - Command exited with return code 1
[2022-03-13 10:26:37,763] {taskinstance.py:1718} ERROR - Task failed with exception
Traceback (most recent call last):
  File "/home/airflow/.local/lib/python3.7/site-packages/airflow/models/taskinstance.py", line 1334, in _run_raw_task
    self._execute_task_with_callbacks(context)
  File "/home/airflow/.local/lib/python3.7/site-packages/airflow/models/taskinstance.py", line 1460, in _execute_task_with_callbacks
    result = self._execute_task(context, self.task)
  File "/home/airflow/.local/lib/python3.7/site-packages/airflow/models/taskinstance.py", line 1516, in _execute_task
    result = execute_callable(context=context)
  File "/home/airflow/.local/lib/python3.7/site-packages/airflow/operators/bash.py", line 188, in execute
    f'Bash command failed. The command returned a non-zero exit code {result.exit_code}.'
airflow.exceptions.AirflowException: Bash command failed. The command returned a non-zero exit code 1.
[2022-03-13 10:26:37,770] {taskinstance.py:1282} INFO - Marking task as FAILED. dag_id=1_init_once_seed_data, task_id=load_seed_data_once, execution_date=20200801T000000, start_date=20220313T102637, end_date=20220313T102637
[2022-03-13 10:26:37,791] {standard_task_runner.py:92} ERROR - Failed to execute job 4 for task load_seed_data_once
Traceback (most recent call last):
  File "/home/airflow/.local/lib/python3.7/site-packages/airflow/task/task_runner/standard_task_runner.py", line 85, in _start_by_fork
    args.func(args, dag=self.dag)
  File "/home/airflow/.local/lib/python3.7/site-packages/airflow/cli/cli_parser.py", line 48, in command
    return func(*args, **kwargs)
  File "/home/airflow/.local/lib/python3.7/site-packages/airflow/utils/cli.py", line 92, in wrapper
    return f(*args, **kwargs)
  File "/home/airflow/.local/lib/python3.7/site-packages/airflow/cli/commands/task_command.py", line 298, in task_run
    _run_task_by_selected_method(args, dag, ti)
  File "/home/airflow/.local/lib/python3.7/site-packages/airflow/cli/commands/task_command.py", line 107, in _run_task_by_selected_method
    _run_raw_task(args, ti)
  File "/home/airflow/.local/lib/python3.7/site-packages/airflow/cli/commands/task_command.py", line 184, in _run_raw_task
    error_file=args.error_file,
  File "/home/airflow/.local/lib/python3.7/site-packages/airflow/utils/session.py", line 70, in wrapper
    return func(*args, session=session, **kwargs)
  File "/home/airflow/.local/lib/python3.7/site-packages/airflow/models/taskinstance.py", line 1334, in _run_raw_task
    self._execute_task_with_callbacks(context)
  File "/home/airflow/.local/lib/python3.7/site-packages/airflow/models/taskinstance.py", line 1460, in _execute_task_with_callbacks
    result = self._execute_task(context, self.task)
  File "/home/airflow/.local/lib/python3.7/site-packages/airflow/models/taskinstance.py", line 1516, in _execute_task
    result = execute_callable(context=context)
  File "/home/airflow/.local/lib/python3.7/site-packages/airflow/operators/bash.py", line 188, in execute
    f'Bash command failed. The command returned a non-zero exit code {result.exit_code}.'
airflow.exceptions.AirflowException: Bash command failed. The command returned a non-zero exit code 1.
[2022-03-13 10:26:37,828] {local_task_job.py:154} INFO - Task exited with return code 1
[2022-03-13 10:26:37,869] {local_task_job.py:264} INFO - 0 downstream tasks scheduled from follow-on schedule check
