[2022-12-02 09:07:45,820] {taskinstance.py:1037} INFO - Dependencies all met for <TaskInstance: 1_init_once_seed_data.load_seed_data_once manual__2022-12-02T09:07:44.368818+00:00 [queued]>
[2022-12-02 09:07:45,827] {taskinstance.py:1037} INFO - Dependencies all met for <TaskInstance: 1_init_once_seed_data.load_seed_data_once manual__2022-12-02T09:07:44.368818+00:00 [queued]>
[2022-12-02 09:07:45,828] {taskinstance.py:1243} INFO - 
--------------------------------------------------------------------------------
[2022-12-02 09:07:45,828] {taskinstance.py:1244} INFO - Starting attempt 1 of 1
[2022-12-02 09:07:45,828] {taskinstance.py:1245} INFO - 
--------------------------------------------------------------------------------
[2022-12-02 09:07:45,844] {taskinstance.py:1264} INFO - Executing <Task(BashOperator): load_seed_data_once> on 2022-12-02 09:07:44.368818+00:00
[2022-12-02 09:07:45,847] {standard_task_runner.py:52} INFO - Started process 87 to run task
[2022-12-02 09:07:45,850] {standard_task_runner.py:76} INFO - Running: ['***', 'tasks', 'run', '1_init_once_seed_data', 'load_seed_data_once', 'manual__2022-12-02T09:07:44.368818+00:00', '--job-id', '105', '--raw', '--subdir', 'DAGS_FOLDER/init.py', '--cfg-path', '/tmp/tmpgoi6pc_t', '--error-file', '/tmp/tmpwqx2auwg']
[2022-12-02 09:07:45,850] {standard_task_runner.py:77} INFO - Job 105: Subtask load_seed_data_once
[2022-12-02 09:07:45,901] {logging_mixin.py:109} INFO - Running <TaskInstance: 1_init_once_seed_data.load_seed_data_once manual__2022-12-02T09:07:44.368818+00:00 [running]> on host 908cd6f7e64f
[2022-12-02 09:07:45,982] {taskinstance.py:1431} INFO - Exporting the following env vars:
AIRFLOW_CTX_DAG_OWNER=***
AIRFLOW_CTX_DAG_ID=1_init_once_seed_data
AIRFLOW_CTX_TASK_ID=load_seed_data_once
AIRFLOW_CTX_EXECUTION_DATE=2022-12-02T09:07:44.368818+00:00
AIRFLOW_CTX_DAG_RUN_ID=manual__2022-12-02T09:07:44.368818+00:00
[2022-12-02 09:07:45,982] {subprocess.py:62} INFO - Tmp dir root location: 
 /tmp
[2022-12-02 09:07:45,983] {subprocess.py:74} INFO - Running command: ['bash', '-c', 'cd /dbt && dbt --no-version-check seed --profiles-dir .']
[2022-12-02 09:07:45,991] {subprocess.py:85} INFO - Output:
[2022-12-02 09:07:48,701] {subprocess.py:89} INFO - usage: dbt [-h] [--version] [-r RECORD_TIMING_INFO] [-d]
[2022-12-02 09:07:48,702] {subprocess.py:89} INFO -            [--log-format {text,json,default}] [--no-write-json]
[2022-12-02 09:07:48,702] {subprocess.py:89} INFO -            [--use-colors | --no-use-colors] [-S] [--warn-error]
[2022-12-02 09:07:48,702] {subprocess.py:89} INFO -            [--partial-parse | --no-partial-parse] [--use-experimental-parser]
[2022-12-02 09:07:48,702] {subprocess.py:89} INFO -            {docs,source,init,clean,debug,deps,list,ls,build,snapshot,rpc,run,compile,parse,test,seed,run-operation}
[2022-12-02 09:07:48,702] {subprocess.py:89} INFO -            ...
[2022-12-02 09:07:48,702] {subprocess.py:89} INFO - dbt: error: unrecognized arguments: --no-version-check
[2022-12-02 09:07:48,813] {subprocess.py:93} INFO - Command exited with return code 2
[2022-12-02 09:07:48,824] {taskinstance.py:1718} ERROR - Task failed with exception
Traceback (most recent call last):
  File "/home/airflow/.local/lib/python3.7/site-packages/airflow/models/taskinstance.py", line 1334, in _run_raw_task
    self._execute_task_with_callbacks(context)
  File "/home/airflow/.local/lib/python3.7/site-packages/airflow/models/taskinstance.py", line 1460, in _execute_task_with_callbacks
    result = self._execute_task(context, self.task)
  File "/home/airflow/.local/lib/python3.7/site-packages/airflow/models/taskinstance.py", line 1516, in _execute_task
    result = execute_callable(context=context)
  File "/home/airflow/.local/lib/python3.7/site-packages/airflow/operators/bash.py", line 188, in execute
    f'Bash command failed. The command returned a non-zero exit code {result.exit_code}.'
airflow.exceptions.AirflowException: Bash command failed. The command returned a non-zero exit code 2.
[2022-12-02 09:07:48,829] {taskinstance.py:1282} INFO - Marking task as FAILED. dag_id=1_init_once_seed_data, task_id=load_seed_data_once, execution_date=20221202T090744, start_date=20221202T090745, end_date=20221202T090748
[2022-12-02 09:07:48,842] {standard_task_runner.py:92} ERROR - Failed to execute job 105 for task load_seed_data_once
Traceback (most recent call last):
  File "/home/airflow/.local/lib/python3.7/site-packages/airflow/task/task_runner/standard_task_runner.py", line 85, in _start_by_fork
    args.func(args, dag=self.dag)
  File "/home/airflow/.local/lib/python3.7/site-packages/airflow/cli/cli_parser.py", line 48, in command
    return func(*args, **kwargs)
  File "/home/airflow/.local/lib/python3.7/site-packages/airflow/utils/cli.py", line 92, in wrapper
    return f(*args, **kwargs)
  File "/home/airflow/.local/lib/python3.7/site-packages/airflow/cli/commands/task_command.py", line 298, in task_run
    _run_task_by_selected_method(args, dag, ti)
  File "/home/airflow/.local/lib/python3.7/site-packages/airflow/cli/commands/task_command.py", line 107, in _run_task_by_selected_method
    _run_raw_task(args, ti)
  File "/home/airflow/.local/lib/python3.7/site-packages/airflow/cli/commands/task_command.py", line 184, in _run_raw_task
    error_file=args.error_file,
  File "/home/airflow/.local/lib/python3.7/site-packages/airflow/utils/session.py", line 70, in wrapper
    return func(*args, session=session, **kwargs)
  File "/home/airflow/.local/lib/python3.7/site-packages/airflow/models/taskinstance.py", line 1334, in _run_raw_task
    self._execute_task_with_callbacks(context)
  File "/home/airflow/.local/lib/python3.7/site-packages/airflow/models/taskinstance.py", line 1460, in _execute_task_with_callbacks
    result = self._execute_task(context, self.task)
  File "/home/airflow/.local/lib/python3.7/site-packages/airflow/models/taskinstance.py", line 1516, in _execute_task
    result = execute_callable(context=context)
  File "/home/airflow/.local/lib/python3.7/site-packages/airflow/operators/bash.py", line 188, in execute
    f'Bash command failed. The command returned a non-zero exit code {result.exit_code}.'
airflow.exceptions.AirflowException: Bash command failed. The command returned a non-zero exit code 2.
[2022-12-02 09:07:48,869] {local_task_job.py:154} INFO - Task exited with return code 1
[2022-12-02 09:07:48,893] {local_task_job.py:264} INFO - 0 downstream tasks scheduled from follow-on schedule check
