[2022-12-02 09:19:26,369] {taskinstance.py:1037} INFO - Dependencies all met for <TaskInstance: 2_daily_transformation_analysis.daily_analysis manual__2022-12-02T09:19:12.859688+00:00 [queued]>
[2022-12-02 09:19:26,379] {taskinstance.py:1037} INFO - Dependencies all met for <TaskInstance: 2_daily_transformation_analysis.daily_analysis manual__2022-12-02T09:19:12.859688+00:00 [queued]>
[2022-12-02 09:19:26,379] {taskinstance.py:1243} INFO - 
--------------------------------------------------------------------------------
[2022-12-02 09:19:26,380] {taskinstance.py:1244} INFO - Starting attempt 1 of 1
[2022-12-02 09:19:26,380] {taskinstance.py:1245} INFO - 
--------------------------------------------------------------------------------
[2022-12-02 09:19:26,392] {taskinstance.py:1264} INFO - Executing <Task(BashOperator): daily_analysis> on 2022-12-02 09:19:12.859688+00:00
[2022-12-02 09:19:26,397] {standard_task_runner.py:52} INFO - Started process 118 to run task
[2022-12-02 09:19:26,399] {standard_task_runner.py:76} INFO - Running: ['***', 'tasks', 'run', '2_daily_transformation_analysis', 'daily_analysis', 'manual__2022-12-02T09:19:12.859688+00:00', '--job-id', '117', '--raw', '--subdir', 'DAGS_FOLDER/transform_and_analysis.py', '--cfg-path', '/tmp/tmpvvdh8vnh', '--error-file', '/tmp/tmpoplubmst']
[2022-12-02 09:19:26,400] {standard_task_runner.py:77} INFO - Job 117: Subtask daily_analysis
[2022-12-02 09:19:26,441] {logging_mixin.py:109} INFO - Running <TaskInstance: 2_daily_transformation_analysis.daily_analysis manual__2022-12-02T09:19:12.859688+00:00 [running]> on host 0027536f38bc
[2022-12-02 09:19:26,517] {taskinstance.py:1431} INFO - Exporting the following env vars:
AIRFLOW_CTX_DAG_OWNER=***
AIRFLOW_CTX_DAG_ID=2_daily_transformation_analysis
AIRFLOW_CTX_TASK_ID=daily_analysis
AIRFLOW_CTX_EXECUTION_DATE=2022-12-02T09:19:12.859688+00:00
AIRFLOW_CTX_DAG_RUN_ID=manual__2022-12-02T09:19:12.859688+00:00
[2022-12-02 09:19:26,518] {subprocess.py:62} INFO - Tmp dir root location: 
 /tmp
[2022-12-02 09:19:26,518] {subprocess.py:74} INFO - Running command: ['bash', '-c', 'cd /dbt && dbt run --no-version-check --models analysis --profiles-dir .']
[2022-12-02 09:19:26,527] {subprocess.py:85} INFO - Output:
[2022-12-02 09:19:29,010] {subprocess.py:89} INFO - Running with dbt=0.21.1
[2022-12-02 09:19:30,206] {subprocess.py:89} INFO - Found 5 models, 0 tests, 0 snapshots, 0 analyses, 374 macros, 0 operations, 3 seed files, 0 sources, 0 exposures
[2022-12-02 09:19:30,208] {subprocess.py:89} INFO - 
[2022-12-02 09:19:32,162] {subprocess.py:89} INFO - 09:19:32 | Concurrency: 4 threads (target='staging')
[2022-12-02 09:19:32,162] {subprocess.py:89} INFO - 09:19:32 |
[2022-12-02 09:19:32,168] {subprocess.py:89} INFO - 09:19:32 | 1 of 2 START view model analysis.hotel_count_by_day.................. [RUN]
[2022-12-02 09:19:32,169] {subprocess.py:89} INFO - 09:19:32 | 2 of 2 START view model analysis.thirty_day_avg_cost................. [RUN]
[2022-12-02 09:19:32,507] {subprocess.py:89} INFO - 09:19:32 | 2 of 2 ERROR creating view model analysis.thirty_day_avg_cost........ [[31mERROR[0m in 0.34s]
[2022-12-02 09:19:33,324] {subprocess.py:89} INFO - 09:19:33 | 1 of 2 OK created view model analysis.hotel_count_by_day............. [[32mOK[0m in 1.15s]
[2022-12-02 09:19:33,460] {subprocess.py:89} INFO - 09:19:33 |
[2022-12-02 09:19:33,460] {subprocess.py:89} INFO - 09:19:33 | Finished running 2 view models in 3.25s.
[2022-12-02 09:19:33,664] {subprocess.py:89} INFO - 
[2022-12-02 09:19:33,665] {subprocess.py:89} INFO - [31mCompleted with 1 error and 0 warnings:[0m
[2022-12-02 09:19:33,665] {subprocess.py:89} INFO - 
[2022-12-02 09:19:33,665] {subprocess.py:89} INFO - [33mRuntime Error in model thirty_day_avg_cost (models/analysis/thirty_day_avg_cost.sql)[0m
[2022-12-02 09:19:33,665] {subprocess.py:89} INFO - 
[2022-12-02 09:19:33,666] {subprocess.py:89} INFO -   [PARSE_SYNTAX_ERROR] Syntax error at or near '"30_DAY_AVG_COST"'(line 11, pos 7)
[2022-12-02 09:19:33,666] {subprocess.py:89} INFO - 
[2022-12-02 09:19:33,666] {subprocess.py:89} INFO -   == SQL ==
[2022-12-02 09:19:33,667] {subprocess.py:89} INFO -   /* {"app": "dbt", "dbt_version": "0.21.1", "profile_name": "dbt", "target_name": "staging", "node_id": "model.my_new_project.thirty_day_avg_cost"} */
[2022-12-02 09:19:33,667] {subprocess.py:89} INFO -   create or replace view analysis.thirty_day_avg_cost
[2022-12-02 09:19:33,667] {subprocess.py:89} INFO - 
[2022-12-02 09:19:33,668] {subprocess.py:89} INFO -     as
[2022-12-02 09:19:33,668] {subprocess.py:89} INFO -       SELECT
[2022-12-02 09:19:33,668] {subprocess.py:89} INFO -     BOOKING_DATE,
[2022-12-02 09:19:33,668] {subprocess.py:89} INFO -     HOTEL,
[2022-12-02 09:19:33,669] {subprocess.py:89} INFO -     COST,
[2022-12-02 09:19:33,669] {subprocess.py:89} INFO -     AVG(COST) OVER (
[2022-12-02 09:19:33,669] {subprocess.py:89} INFO -       ORDER BY BOOKING_DATE ROWS BETWEEN 29 PRECEDING AND CURRENT ROW
[2022-12-02 09:19:33,669] {subprocess.py:89} INFO -     ) as "30_DAY_AVG_COST",
[2022-12-02 09:19:33,669] {subprocess.py:89} INFO -   -------^^^
[2022-12-02 09:19:33,670] {subprocess.py:89} INFO -     COST -   AVG(COST) OVER (
[2022-12-02 09:19:33,670] {subprocess.py:89} INFO -       ORDER BY BOOKING_DATE ROWS BETWEEN 29 PRECEDING AND CURRENT ROW
[2022-12-02 09:19:33,670] {subprocess.py:89} INFO -     ) as "DIFF_BTW_ACTUAL_AVG"
[2022-12-02 09:19:33,670] {subprocess.py:89} INFO -   FROM transform.prepped_data
[2022-12-02 09:19:33,670] {subprocess.py:89} INFO - 
[2022-12-02 09:19:33,671] {subprocess.py:89} INFO - 
[2022-12-02 09:19:33,671] {subprocess.py:89} INFO - Done. PASS=1 WARN=0 ERROR=1 SKIP=0 TOTAL=2
[2022-12-02 09:19:34,902] {subprocess.py:93} INFO - Command exited with return code 1
[2022-12-02 09:19:34,912] {taskinstance.py:1718} ERROR - Task failed with exception
Traceback (most recent call last):
  File "/home/airflow/.local/lib/python3.7/site-packages/airflow/models/taskinstance.py", line 1334, in _run_raw_task
    self._execute_task_with_callbacks(context)
  File "/home/airflow/.local/lib/python3.7/site-packages/airflow/models/taskinstance.py", line 1460, in _execute_task_with_callbacks
    result = self._execute_task(context, self.task)
  File "/home/airflow/.local/lib/python3.7/site-packages/airflow/models/taskinstance.py", line 1516, in _execute_task
    result = execute_callable(context=context)
  File "/home/airflow/.local/lib/python3.7/site-packages/airflow/operators/bash.py", line 188, in execute
    f'Bash command failed. The command returned a non-zero exit code {result.exit_code}.'
airflow.exceptions.AirflowException: Bash command failed. The command returned a non-zero exit code 1.
[2022-12-02 09:19:34,917] {taskinstance.py:1282} INFO - Marking task as FAILED. dag_id=2_daily_transformation_analysis, task_id=daily_analysis, execution_date=20221202T091912, start_date=20221202T091926, end_date=20221202T091934
[2022-12-02 09:19:34,933] {standard_task_runner.py:92} ERROR - Failed to execute job 117 for task daily_analysis
Traceback (most recent call last):
  File "/home/airflow/.local/lib/python3.7/site-packages/airflow/task/task_runner/standard_task_runner.py", line 85, in _start_by_fork
    args.func(args, dag=self.dag)
  File "/home/airflow/.local/lib/python3.7/site-packages/airflow/cli/cli_parser.py", line 48, in command
    return func(*args, **kwargs)
  File "/home/airflow/.local/lib/python3.7/site-packages/airflow/utils/cli.py", line 92, in wrapper
    return f(*args, **kwargs)
  File "/home/airflow/.local/lib/python3.7/site-packages/airflow/cli/commands/task_command.py", line 298, in task_run
    _run_task_by_selected_method(args, dag, ti)
  File "/home/airflow/.local/lib/python3.7/site-packages/airflow/cli/commands/task_command.py", line 107, in _run_task_by_selected_method
    _run_raw_task(args, ti)
  File "/home/airflow/.local/lib/python3.7/site-packages/airflow/cli/commands/task_command.py", line 184, in _run_raw_task
    error_file=args.error_file,
  File "/home/airflow/.local/lib/python3.7/site-packages/airflow/utils/session.py", line 70, in wrapper
    return func(*args, session=session, **kwargs)
  File "/home/airflow/.local/lib/python3.7/site-packages/airflow/models/taskinstance.py", line 1334, in _run_raw_task
    self._execute_task_with_callbacks(context)
  File "/home/airflow/.local/lib/python3.7/site-packages/airflow/models/taskinstance.py", line 1460, in _execute_task_with_callbacks
    result = self._execute_task(context, self.task)
  File "/home/airflow/.local/lib/python3.7/site-packages/airflow/models/taskinstance.py", line 1516, in _execute_task
    result = execute_callable(context=context)
  File "/home/airflow/.local/lib/python3.7/site-packages/airflow/operators/bash.py", line 188, in execute
    f'Bash command failed. The command returned a non-zero exit code {result.exit_code}.'
airflow.exceptions.AirflowException: Bash command failed. The command returned a non-zero exit code 1.
[2022-12-02 09:19:34,954] {local_task_job.py:154} INFO - Task exited with return code 1
[2022-12-02 09:19:34,979] {local_task_job.py:264} INFO - 0 downstream tasks scheduled from follow-on schedule check
