[2022-11-30 06:48:31,144] {taskinstance.py:1037} INFO - Dependencies all met for <TaskInstance: example_snowflake.snowflake_copy_bookings scheduled__2022-11-29T06:48:29.063444+00:00 [queued]>
[2022-11-30 06:48:31,150] {taskinstance.py:1037} INFO - Dependencies all met for <TaskInstance: example_snowflake.snowflake_copy_bookings scheduled__2022-11-29T06:48:29.063444+00:00 [queued]>
[2022-11-30 06:48:31,150] {taskinstance.py:1243} INFO - 
--------------------------------------------------------------------------------
[2022-11-30 06:48:31,150] {taskinstance.py:1244} INFO - Starting attempt 1 of 1
[2022-11-30 06:48:31,150] {taskinstance.py:1245} INFO - 
--------------------------------------------------------------------------------
[2022-11-30 06:48:31,161] {taskinstance.py:1264} INFO - Executing <Task(SnowflakeOperator): snowflake_copy_bookings> on 2022-11-29 06:48:29.063444+00:00
[2022-11-30 06:48:31,165] {standard_task_runner.py:52} INFO - Started process 93 to run task
[2022-11-30 06:48:31,167] {standard_task_runner.py:76} INFO - Running: ['***', 'tasks', 'run', 'example_snowflake', 'snowflake_copy_bookings', 'scheduled__2022-11-29T06:48:29.063444+00:00', '--job-id', '84', '--raw', '--subdir', 'DAGS_FOLDER/load_snowflake.py', '--cfg-path', '/tmp/tmpptw4cbno', '--error-file', '/tmp/tmp_gg3ka3o']
[2022-11-30 06:48:31,168] {standard_task_runner.py:77} INFO - Job 84: Subtask snowflake_copy_bookings
[2022-11-30 06:48:31,221] {logging_mixin.py:109} INFO - Running <TaskInstance: example_snowflake.snowflake_copy_bookings scheduled__2022-11-29T06:48:29.063444+00:00 [running]> on host 86cba9f2647b
[2022-11-30 06:48:31,285] {taskinstance.py:1431} INFO - Exporting the following env vars:
AIRFLOW_CTX_DAG_OWNER=***
AIRFLOW_CTX_DAG_ID=example_snowflake
AIRFLOW_CTX_TASK_ID=snowflake_copy_bookings
AIRFLOW_CTX_EXECUTION_DATE=2022-11-29T06:48:29.063444+00:00
AIRFLOW_CTX_DAG_RUN_ID=scheduled__2022-11-29T06:48:29.063444+00:00
[2022-11-30 06:48:31,286] {snowflake.py:127} INFO - Executing: copy into PUBLIC.BOOKINGS_1 from s3://gw-test-open-snowflake/***/ FILES=('bookings_1.csv') FILE_FORMAT=(TYPE='CSV' SKIP_HEADER=1);copy into PUBLIC.BOOKINGS_2 from s3://gw-test-open-snowflake/***/ FILES=('bookings_2.csv') FILE_FORMAT=(TYPE='CSV' SKIP_HEADER=1);
[2022-11-30 06:48:31,292] {base.py:79} INFO - Using connection to: id: snowflake_conn. Host: ms36734.ap-southeast-2.snowflakecomputing.com, Port: None, Schema: public, Login: ggww128, Password: ***, extra: {'extra__snowflake__account': 'ms36734', 'extra__snowflake__database': 'DEMO_DBT', 'extra__snowflake__insecure_mode': False, 'extra__snowflake__region': 'ap-southeast-2', 'extra__snowflake__role': 'dbt_DEV_ROLE', 'extra__snowflake__warehouse': 'dbt_DEV_WH'}
[2022-11-30 06:48:31,293] {connection.py:262} INFO - Snowflake Connector for Python Version: 2.4.6, Python Version: 3.7.12, Platform: Linux-5.18.10-051810-generic-x86_64-with-debian-10.11
[2022-11-30 06:48:31,293] {connection.py:869} INFO - This connection is in OCSP Fail Open Mode. TLS Certificates would be checked for validity and revocation status. Any other Certificate Revocation related exceptions or OCSP Responder failures would be disregarded in favor of connectivity.
[2022-11-30 06:48:31,293] {connection.py:886} INFO - Setting use_openssl_only mode to False
[2022-11-30 06:48:31,848] {cursor.py:637} INFO - query: [ALTER SESSION SET autocommit=True]
[2022-11-30 06:48:32,020] {cursor.py:661} INFO - query execution done
[2022-11-30 06:48:32,021] {snowflake.py:283} INFO - Running statement: copy into PUBLIC.BOOKINGS_1 from s3://gw-test-open-snowflake/***/ FILES=('bookings_1.csv') FILE_FORMAT=(TYPE='CSV' SKIP_HEADER=1);, parameters: None
[2022-11-30 06:48:32,021] {cursor.py:637} INFO - query: [copy into PUBLIC.BOOKINGS_1 from s3://gw-test-open-snowflake/***/ FILES=('bo...]
[2022-11-30 06:48:35,302] {cursor.py:661} INFO - query execution done
[2022-11-30 06:48:35,307] {connection.py:499} INFO - closed
[2022-11-30 06:48:35,328] {connection.py:502} INFO - No async queries seem to be running, deleting session
[2022-11-30 06:48:35,388] {taskinstance.py:1718} ERROR - Task failed with exception
Traceback (most recent call last):
  File "/home/airflow/.local/lib/python3.7/site-packages/airflow/models/taskinstance.py", line 1334, in _run_raw_task
    self._execute_task_with_callbacks(context)
  File "/home/airflow/.local/lib/python3.7/site-packages/airflow/models/taskinstance.py", line 1460, in _execute_task_with_callbacks
    result = self._execute_task(context, self.task)
  File "/home/airflow/.local/lib/python3.7/site-packages/airflow/models/taskinstance.py", line 1516, in _execute_task
    result = execute_callable(context=context)
  File "/home/airflow/.local/lib/python3.7/site-packages/airflow/providers/snowflake/operators/snowflake.py", line 129, in execute
    execution_info = hook.run(self.sql, autocommit=self.autocommit, parameters=self.parameters)
  File "/home/airflow/.local/lib/python3.7/site-packages/airflow/providers/snowflake/hooks/snowflake.py", line 287, in run
    cur.execute(sql_statement)
  File "/home/airflow/.local/lib/python3.7/site-packages/snowflake/connector/cursor.py", line 722, in execute
    self.connection, self, ProgrammingError, errvalue
  File "/home/airflow/.local/lib/python3.7/site-packages/snowflake/connector/errors.py", line 258, in errorhandler_wrapper
    cursor.errorhandler(connection, cursor, error_class, error_value)
  File "/home/airflow/.local/lib/python3.7/site-packages/snowflake/connector/errors.py", line 195, in default_errorhandler
    cursor=cursor,
snowflake.connector.errors.ProgrammingError: 091017 (22000): 01a8a658-3201-33b7-0000-aa290003100e: S3 bucket 'gw-test-open-snowflake' does not exist or not authorized.
[2022-11-30 06:48:35,400] {taskinstance.py:1282} INFO - Marking task as FAILED. dag_id=example_snowflake, task_id=snowflake_copy_bookings, execution_date=20221129T064829, start_date=20221130T064831, end_date=20221130T064835
[2022-11-30 06:48:35,418] {standard_task_runner.py:92} ERROR - Failed to execute job 84 for task snowflake_copy_bookings
Traceback (most recent call last):
  File "/home/airflow/.local/lib/python3.7/site-packages/airflow/task/task_runner/standard_task_runner.py", line 85, in _start_by_fork
    args.func(args, dag=self.dag)
  File "/home/airflow/.local/lib/python3.7/site-packages/airflow/cli/cli_parser.py", line 48, in command
    return func(*args, **kwargs)
  File "/home/airflow/.local/lib/python3.7/site-packages/airflow/utils/cli.py", line 92, in wrapper
    return f(*args, **kwargs)
  File "/home/airflow/.local/lib/python3.7/site-packages/airflow/cli/commands/task_command.py", line 298, in task_run
    _run_task_by_selected_method(args, dag, ti)
  File "/home/airflow/.local/lib/python3.7/site-packages/airflow/cli/commands/task_command.py", line 107, in _run_task_by_selected_method
    _run_raw_task(args, ti)
  File "/home/airflow/.local/lib/python3.7/site-packages/airflow/cli/commands/task_command.py", line 184, in _run_raw_task
    error_file=args.error_file,
  File "/home/airflow/.local/lib/python3.7/site-packages/airflow/utils/session.py", line 70, in wrapper
    return func(*args, session=session, **kwargs)
  File "/home/airflow/.local/lib/python3.7/site-packages/airflow/models/taskinstance.py", line 1334, in _run_raw_task
    self._execute_task_with_callbacks(context)
  File "/home/airflow/.local/lib/python3.7/site-packages/airflow/models/taskinstance.py", line 1460, in _execute_task_with_callbacks
    result = self._execute_task(context, self.task)
  File "/home/airflow/.local/lib/python3.7/site-packages/airflow/models/taskinstance.py", line 1516, in _execute_task
    result = execute_callable(context=context)
  File "/home/airflow/.local/lib/python3.7/site-packages/airflow/providers/snowflake/operators/snowflake.py", line 129, in execute
    execution_info = hook.run(self.sql, autocommit=self.autocommit, parameters=self.parameters)
  File "/home/airflow/.local/lib/python3.7/site-packages/airflow/providers/snowflake/hooks/snowflake.py", line 287, in run
    cur.execute(sql_statement)
  File "/home/airflow/.local/lib/python3.7/site-packages/snowflake/connector/cursor.py", line 722, in execute
    self.connection, self, ProgrammingError, errvalue
  File "/home/airflow/.local/lib/python3.7/site-packages/snowflake/connector/errors.py", line 258, in errorhandler_wrapper
    cursor.errorhandler(connection, cursor, error_class, error_value)
  File "/home/airflow/.local/lib/python3.7/site-packages/snowflake/connector/errors.py", line 195, in default_errorhandler
    cursor=cursor,
snowflake.connector.errors.ProgrammingError: 091017 (22000): 01a8a658-3201-33b7-0000-aa290003100e: S3 bucket 'gw-test-open-snowflake' does not exist or not authorized.
[2022-11-30 06:48:35,429] {local_task_job.py:154} INFO - Task exited with return code 1
[2022-11-30 06:48:35,461] {local_task_job.py:264} INFO - 0 downstream tasks scheduled from follow-on schedule check
