[2022-03-13 10:40:49,245] {taskinstance.py:1037} INFO - Dependencies all met for <TaskInstance: 1_init_once_seed_data.load_seed_data_once manual__2022-03-13T10:40:47.995708+00:00 [queued]>
[2022-03-13 10:40:49,254] {taskinstance.py:1037} INFO - Dependencies all met for <TaskInstance: 1_init_once_seed_data.load_seed_data_once manual__2022-03-13T10:40:47.995708+00:00 [queued]>
[2022-03-13 10:40:49,254] {taskinstance.py:1243} INFO - 
--------------------------------------------------------------------------------
[2022-03-13 10:40:49,254] {taskinstance.py:1244} INFO - Starting attempt 1 of 1
[2022-03-13 10:40:49,254] {taskinstance.py:1245} INFO - 
--------------------------------------------------------------------------------
[2022-03-13 10:40:49,270] {taskinstance.py:1264} INFO - Executing <Task(BashOperator): load_seed_data_once> on 2022-03-13 10:40:47.995708+00:00
[2022-03-13 10:40:49,274] {standard_task_runner.py:52} INFO - Started process 394 to run task
[2022-03-13 10:40:49,276] {standard_task_runner.py:76} INFO - Running: ['***', 'tasks', 'run', '1_init_once_seed_data', 'load_seed_data_once', 'manual__2022-03-13T10:40:47.995708+00:00', '--job-id', '7', '--raw', '--subdir', 'DAGS_FOLDER/init.py', '--cfg-path', '/tmp/tmpnd9yb_9c', '--error-file', '/tmp/tmptlot1td2']
[2022-03-13 10:40:49,276] {standard_task_runner.py:77} INFO - Job 7: Subtask load_seed_data_once
[2022-03-13 10:40:49,322] {logging_mixin.py:109} INFO - Running <TaskInstance: 1_init_once_seed_data.load_seed_data_once manual__2022-03-13T10:40:47.995708+00:00 [running]> on host 08d328823fdc
[2022-03-13 10:40:49,407] {taskinstance.py:1431} INFO - Exporting the following env vars:
AIRFLOW_CTX_DAG_OWNER=***
AIRFLOW_CTX_DAG_ID=1_init_once_seed_data
AIRFLOW_CTX_TASK_ID=load_seed_data_once
AIRFLOW_CTX_EXECUTION_DATE=2022-03-13T10:40:47.995708+00:00
AIRFLOW_CTX_DAG_RUN_ID=manual__2022-03-13T10:40:47.995708+00:00
[2022-03-13 10:40:49,407] {subprocess.py:62} INFO - Tmp dir root location: 
 /tmp
[2022-03-13 10:40:49,408] {subprocess.py:74} INFO - Running command: ['bash', '-c', 'cd /dbt && dbt seed --profiles-dir .']
[2022-03-13 10:40:49,417] {subprocess.py:85} INFO - Output:
[2022-03-13 10:40:50,826] {subprocess.py:89} INFO - Running with dbt=0.19.0
[2022-03-13 10:40:52,648] {subprocess.py:89} INFO - Encountered an error while reading the project:
[2022-03-13 10:40:52,648] {subprocess.py:89} INFO -   ERROR: Runtime Error
[2022-03-13 10:40:52,648] {subprocess.py:89} INFO -   at path []: Additional properties are not allowed ('model-paths', 'seed-paths' were unexpected)
[2022-03-13 10:40:52,648] {subprocess.py:89} INFO - 
[2022-03-13 10:40:52,649] {subprocess.py:89} INFO - Error encountered in /dbt/dbt_project.yml
[2022-03-13 10:40:52,649] {subprocess.py:89} INFO - Encountered an error:
[2022-03-13 10:40:52,649] {subprocess.py:89} INFO - Runtime Error
[2022-03-13 10:40:52,649] {subprocess.py:89} INFO -   Could not run dbt
[2022-03-13 10:40:52,915] {subprocess.py:93} INFO - Command exited with return code 2
[2022-03-13 10:40:52,931] {taskinstance.py:1718} ERROR - Task failed with exception
Traceback (most recent call last):
  File "/home/airflow/.local/lib/python3.7/site-packages/airflow/models/taskinstance.py", line 1334, in _run_raw_task
    self._execute_task_with_callbacks(context)
  File "/home/airflow/.local/lib/python3.7/site-packages/airflow/models/taskinstance.py", line 1460, in _execute_task_with_callbacks
    result = self._execute_task(context, self.task)
  File "/home/airflow/.local/lib/python3.7/site-packages/airflow/models/taskinstance.py", line 1516, in _execute_task
    result = execute_callable(context=context)
  File "/home/airflow/.local/lib/python3.7/site-packages/airflow/operators/bash.py", line 188, in execute
    f'Bash command failed. The command returned a non-zero exit code {result.exit_code}.'
airflow.exceptions.AirflowException: Bash command failed. The command returned a non-zero exit code 2.
[2022-03-13 10:40:52,941] {taskinstance.py:1282} INFO - Marking task as FAILED. dag_id=1_init_once_seed_data, task_id=load_seed_data_once, execution_date=20220313T104047, start_date=20220313T104049, end_date=20220313T104052
[2022-03-13 10:40:52,959] {standard_task_runner.py:92} ERROR - Failed to execute job 7 for task load_seed_data_once
Traceback (most recent call last):
  File "/home/airflow/.local/lib/python3.7/site-packages/airflow/task/task_runner/standard_task_runner.py", line 85, in _start_by_fork
    args.func(args, dag=self.dag)
  File "/home/airflow/.local/lib/python3.7/site-packages/airflow/cli/cli_parser.py", line 48, in command
    return func(*args, **kwargs)
  File "/home/airflow/.local/lib/python3.7/site-packages/airflow/utils/cli.py", line 92, in wrapper
    return f(*args, **kwargs)
  File "/home/airflow/.local/lib/python3.7/site-packages/airflow/cli/commands/task_command.py", line 298, in task_run
    _run_task_by_selected_method(args, dag, ti)
  File "/home/airflow/.local/lib/python3.7/site-packages/airflow/cli/commands/task_command.py", line 107, in _run_task_by_selected_method
    _run_raw_task(args, ti)
  File "/home/airflow/.local/lib/python3.7/site-packages/airflow/cli/commands/task_command.py", line 184, in _run_raw_task
    error_file=args.error_file,
  File "/home/airflow/.local/lib/python3.7/site-packages/airflow/utils/session.py", line 70, in wrapper
    return func(*args, session=session, **kwargs)
  File "/home/airflow/.local/lib/python3.7/site-packages/airflow/models/taskinstance.py", line 1334, in _run_raw_task
    self._execute_task_with_callbacks(context)
  File "/home/airflow/.local/lib/python3.7/site-packages/airflow/models/taskinstance.py", line 1460, in _execute_task_with_callbacks
    result = self._execute_task(context, self.task)
  File "/home/airflow/.local/lib/python3.7/site-packages/airflow/models/taskinstance.py", line 1516, in _execute_task
    result = execute_callable(context=context)
  File "/home/airflow/.local/lib/python3.7/site-packages/airflow/operators/bash.py", line 188, in execute
    f'Bash command failed. The command returned a non-zero exit code {result.exit_code}.'
airflow.exceptions.AirflowException: Bash command failed. The command returned a non-zero exit code 2.
[2022-03-13 10:40:52,977] {local_task_job.py:154} INFO - Task exited with return code 1
[2022-03-13 10:40:53,031] {local_task_job.py:264} INFO - 0 downstream tasks scheduled from follow-on schedule check
